2018-03-27 23:18:26,883 INFO: Microblog startup [in C:\Users\RH Laptop\Documents\PythonFiles\Git_Microblog\app\__init__.py:46
2018-03-27 23:34:23,032 INFO: Microblog startup [in C:\Users\RH Laptop\Documents\PythonFiles\Git_Microblog\app\__init__.py:46
2018-03-27 23:34:29,742 ERROR: Exception on /edit_profile [POST] [in c:\users\rhlapt~1\docume~1\python~1\venvs~1\flaskw~1\lib\site-packages\flask\app.py:1560
Traceback (most recent call last):
  File "c:\users\rhlapt~1\docume~1\python~1\venvs~1\flaskw~1\lib\site-packages\flask\app.py", line 1982, in wsgi_app
    response = self.full_dispatch_request()
  File "c:\users\rhlapt~1\docume~1\python~1\venvs~1\flaskw~1\lib\site-packages\flask\app.py", line 1614, in full_dispatch_request
    rv = self.handle_user_exception(e)
  File "c:\users\rhlapt~1\docume~1\python~1\venvs~1\flaskw~1\lib\site-packages\flask\app.py", line 1517, in handle_user_exception
    reraise(exc_type, exc_value, tb)
  File "c:\users\rhlapt~1\docume~1\python~1\venvs~1\flaskw~1\lib\site-packages\flask\_compat.py", line 33, in reraise
    raise value
  File "c:\users\rhlapt~1\docume~1\python~1\venvs~1\flaskw~1\lib\site-packages\flask\app.py", line 1612, in full_dispatch_request
    rv = self.dispatch_request()
  File "c:\users\rhlapt~1\docume~1\python~1\venvs~1\flaskw~1\lib\site-packages\flask\app.py", line 1598, in dispatch_request
    return self.view_functions[rule.endpoint](**req.view_args)
  File "c:\users\rhlapt~1\docume~1\python~1\venvs~1\flaskw~1\lib\site-packages\flask_login\utils.py", line 261, in decorated_view
    return func(*args, **kwargs)
  File "C:\Users\RH Laptop\Documents\PythonFiles\Git_Microblog\app\routes.py", line 87, in edit_profile
    if form.validate_on_submit():
  File "c:\users\rhlapt~1\docume~1\python~1\venvs~1\flaskw~1\lib\site-packages\flask_wtf\form.py", line 101, in validate_on_submit
    return self.is_submitted() and self.validate()
  File "c:\users\rhlapt~1\docume~1\python~1\venvs~1\flaskw~1\lib\site-packages\wtforms\form.py", line 310, in validate
    return super(Form, self).validate(extra)
  File "c:\users\rhlapt~1\docume~1\python~1\venvs~1\flaskw~1\lib\site-packages\wtforms\form.py", line 152, in validate
    if not field.validate(self, extra):
  File "c:\users\rhlapt~1\docume~1\python~1\venvs~1\flaskw~1\lib\site-packages\wtforms\fields\core.py", line 204, in validate
    stop_validation = self._run_validation_chain(form, chain)
  File "c:\users\rhlapt~1\docume~1\python~1\venvs~1\flaskw~1\lib\site-packages\wtforms\fields\core.py", line 224, in _run_validation_chain
    validator(form, self)
  File "C:\Users\RH Laptop\Documents\PythonFiles\Git_Microblog\app\forms.py", line 42, in validate_username
    if username_data != self.original_username:
NameError: name 'username_data' is not defined
2018-03-27 23:34:52,516 ERROR: Exception on /edit_profile [POST] [in c:\users\rhlapt~1\docume~1\python~1\venvs~1\flaskw~1\lib\site-packages\flask\app.py:1560
Traceback (most recent call last):
  File "c:\users\rhlapt~1\docume~1\python~1\venvs~1\flaskw~1\lib\site-packages\flask\app.py", line 1982, in wsgi_app
    response = self.full_dispatch_request()
  File "c:\users\rhlapt~1\docume~1\python~1\venvs~1\flaskw~1\lib\site-packages\flask\app.py", line 1614, in full_dispatch_request
    rv = self.handle_user_exception(e)
  File "c:\users\rhlapt~1\docume~1\python~1\venvs~1\flaskw~1\lib\site-packages\flask\app.py", line 1517, in handle_user_exception
    reraise(exc_type, exc_value, tb)
  File "c:\users\rhlapt~1\docume~1\python~1\venvs~1\flaskw~1\lib\site-packages\flask\_compat.py", line 33, in reraise
    raise value
  File "c:\users\rhlapt~1\docume~1\python~1\venvs~1\flaskw~1\lib\site-packages\flask\app.py", line 1612, in full_dispatch_request
    rv = self.dispatch_request()
  File "c:\users\rhlapt~1\docume~1\python~1\venvs~1\flaskw~1\lib\site-packages\flask\app.py", line 1598, in dispatch_request
    return self.view_functions[rule.endpoint](**req.view_args)
  File "c:\users\rhlapt~1\docume~1\python~1\venvs~1\flaskw~1\lib\site-packages\flask_login\utils.py", line 261, in decorated_view
    return func(*args, **kwargs)
  File "C:\Users\RH Laptop\Documents\PythonFiles\Git_Microblog\app\routes.py", line 87, in edit_profile
    if form.validate_on_submit():
  File "c:\users\rhlapt~1\docume~1\python~1\venvs~1\flaskw~1\lib\site-packages\flask_wtf\form.py", line 101, in validate_on_submit
    return self.is_submitted() and self.validate()
  File "c:\users\rhlapt~1\docume~1\python~1\venvs~1\flaskw~1\lib\site-packages\wtforms\form.py", line 310, in validate
    return super(Form, self).validate(extra)
  File "c:\users\rhlapt~1\docume~1\python~1\venvs~1\flaskw~1\lib\site-packages\wtforms\form.py", line 152, in validate
    if not field.validate(self, extra):
  File "c:\users\rhlapt~1\docume~1\python~1\venvs~1\flaskw~1\lib\site-packages\wtforms\fields\core.py", line 204, in validate
    stop_validation = self._run_validation_chain(form, chain)
  File "c:\users\rhlapt~1\docume~1\python~1\venvs~1\flaskw~1\lib\site-packages\wtforms\fields\core.py", line 224, in _run_validation_chain
    validator(form, self)
  File "C:\Users\RH Laptop\Documents\PythonFiles\Git_Microblog\app\forms.py", line 42, in validate_username
    if username_data != self.original_username:
NameError: name 'username_data' is not defined
2018-03-27 23:35:03,660 ERROR: Exception on /edit_profile [POST] [in c:\users\rhlapt~1\docume~1\python~1\venvs~1\flaskw~1\lib\site-packages\flask\app.py:1560
Traceback (most recent call last):
  File "c:\users\rhlapt~1\docume~1\python~1\venvs~1\flaskw~1\lib\site-packages\flask\app.py", line 1982, in wsgi_app
    response = self.full_dispatch_request()
  File "c:\users\rhlapt~1\docume~1\python~1\venvs~1\flaskw~1\lib\site-packages\flask\app.py", line 1614, in full_dispatch_request
    rv = self.handle_user_exception(e)
  File "c:\users\rhlapt~1\docume~1\python~1\venvs~1\flaskw~1\lib\site-packages\flask\app.py", line 1517, in handle_user_exception
    reraise(exc_type, exc_value, tb)
  File "c:\users\rhlapt~1\docume~1\python~1\venvs~1\flaskw~1\lib\site-packages\flask\_compat.py", line 33, in reraise
    raise value
  File "c:\users\rhlapt~1\docume~1\python~1\venvs~1\flaskw~1\lib\site-packages\flask\app.py", line 1612, in full_dispatch_request
    rv = self.dispatch_request()
  File "c:\users\rhlapt~1\docume~1\python~1\venvs~1\flaskw~1\lib\site-packages\flask\app.py", line 1598, in dispatch_request
    return self.view_functions[rule.endpoint](**req.view_args)
  File "c:\users\rhlapt~1\docume~1\python~1\venvs~1\flaskw~1\lib\site-packages\flask_login\utils.py", line 261, in decorated_view
    return func(*args, **kwargs)
  File "C:\Users\RH Laptop\Documents\PythonFiles\Git_Microblog\app\routes.py", line 87, in edit_profile
    if form.validate_on_submit():
  File "c:\users\rhlapt~1\docume~1\python~1\venvs~1\flaskw~1\lib\site-packages\flask_wtf\form.py", line 101, in validate_on_submit
    return self.is_submitted() and self.validate()
  File "c:\users\rhlapt~1\docume~1\python~1\venvs~1\flaskw~1\lib\site-packages\wtforms\form.py", line 310, in validate
    return super(Form, self).validate(extra)
  File "c:\users\rhlapt~1\docume~1\python~1\venvs~1\flaskw~1\lib\site-packages\wtforms\form.py", line 152, in validate
    if not field.validate(self, extra):
  File "c:\users\rhlapt~1\docume~1\python~1\venvs~1\flaskw~1\lib\site-packages\wtforms\fields\core.py", line 204, in validate
    stop_validation = self._run_validation_chain(form, chain)
  File "c:\users\rhlapt~1\docume~1\python~1\venvs~1\flaskw~1\lib\site-packages\wtforms\fields\core.py", line 224, in _run_validation_chain
    validator(form, self)
  File "C:\Users\RH Laptop\Documents\PythonFiles\Git_Microblog\app\forms.py", line 42, in validate_username
    if username_data != self.original_username:
NameError: name 'username_data' is not defined
2018-03-27 23:36:07,500 INFO: Microblog startup [in C:\Users\RH Laptop\Documents\PythonFiles\Git_Microblog\app\__init__.py:46
2018-03-27 23:39:18,215 INFO: Microblog startup [in C:\Users\RH Laptop\Documents\PythonFiles\Git_Microblog\app\__init__.py:46
2018-03-28 10:30:45,165 INFO: Microblog startup [in C:\Users\RH Laptop\Documents\PythonFiles\Git_Microblog\app\__init__.py:46
2018-03-28 11:12:08,598 INFO: Microblog startup [in C:\Users\RH Laptop\Documents\PythonFiles\Git_Microblog\app\__init__.py:46
2018-03-28 11:12:13,858 INFO: Microblog startup [in C:\Users\RH Laptop\Documents\PythonFiles\Git_Microblog\app\__init__.py:46
2018-03-28 21:56:39,725 INFO: Microblog startup [in C:\Users\RH Laptop\Documents\PythonFiles\Git_Microblog\app\__init__.py:46
2018-04-01 20:27:33,779 INFO: Microblog startup [in C:\Users\RH Laptop\Documents\PythonFiles\Git_Microblog\app\__init__.py:46
2018-04-01 20:31:43,968 INFO: Microblog startup [in C:\Users\RH Laptop\Documents\PythonFiles\Git_Microblog\app\__init__.py:46
2018-04-01 20:32:26,940 INFO: Microblog startup [in C:\Users\RH Laptop\Documents\PythonFiles\Git_Microblog\app\__init__.py:46
2018-04-01 20:33:23,054 INFO: Microblog startup [in C:\Users\RH Laptop\Documents\PythonFiles\Git_Microblog\app\__init__.py:46
2018-04-01 21:26:13,657 INFO: Microblog startup [in C:\Users\RH Laptop\Documents\PythonFiles\Git_Microblog\app\__init__.py:46
2018-04-01 21:28:48,776 INFO: Microblog startup [in C:\Users\RH Laptop\Documents\PythonFiles\Git_Microblog\app\__init__.py:46
2018-04-01 21:35:27,585 INFO: Microblog startup [in C:\Users\RH Laptop\Documents\PythonFiles\Git_Microblog\app\__init__.py:46
